Workbook

Sheet 001_population_health_zone_zs
A1: Province | B1: Code Province | C1: Territoire | D1: Code Terrtoire | E1: Zone de sante | F1: Pcode ZS | G1: Population 2024 | H1: Homme | I1: Homme | J1: Homme | K1: Homme | L1: Homme | M1: Homme | N1: Homme | O1: Homme | P1: Homme | Q1: Homme | R1: Homme | S1: Homme | T1: Homme | U1: Homme | V1: Homme | W1: Homme | X1: Homme | Y1: Homme | Z1: Homme | AA1: Homme | AB1: Homme | AD1: Femme | AE1: Femme | AF1: Femme | AG1: Femme | AH1: Femme | AI1: Femme | AJ1: Femme | AK1: Femme | AL1: Femme | AM1: Femme | AN1: Femme | AO1: Femme | AP1: Femme | AQ1: Femme | AR1: Femme | AS1: Femme | AT1: Femme | AU1: Femme | AV1: Femme | AW1: Femme | AX1: Femme | BA1: Population 2023 | BB1: Femme | BC1: Ratio | BD1: Homme
A2: Kinshasa | B2: CD10 | C2: Kinshasa | D2: CD1000 | E2: Bandalungwa | F2: CD1000ZS01 | G2: 337289 | H2: =INDEX([1]ratio_ins!F:F,MATCH('001_population_health_zone_zs'!$B$2,[1]ratio_ins!$B:$B,0))*$G2*INDEX([1]ratio_ins!$C:$C,MATCH('001_population_health_zone_zs'!$B2,[1]ratio_ins!$B:$B,0)) -> 35458.181 | I2: =INDEX([1]ratio_ins!G:G,MATCH('001_population_health_zone_zs'!$B$2,[1]ratio_ins!$B:$B,0))*$G2*INDEX([1]ratio_ins!$C:$C,MATCH('001_population_health_zone_zs'!$B2,[1]ratio_ins!$B:$B,0)) -> 29011.239 | J2: =INDEX([1]ratio_ins!H:H,MATCH('001_population_health_zone_zs'!$B$2,[1]ratio_ins!$B:$B,0))*$G2*INDEX([1]ratio_ins!$C:$C,MATCH('001_population_health_zone_zs'!$B2,[1]ratio_ins!$B:$B,0)) -> 22903.61 | K2: =INDEX([1]ratio_ins!I:I,MATCH('001_population_health_zone_zs'!$B$2,[1]ratio_ins!$B:$B,0))*$G2*INDEX([1]ratio_ins!$C:$C,MATCH('001_population_health_zone_zs'!$B2,[1]ratio_ins!$B:$B,0)) -> 14081.478 | L2: =INDEX([1]ratio_ins!J:J,MATCH('001_population_health_zone_zs'!$B$2,[1]ratio_ins!$B:$B,0))*$G2*INDEX([1]ratio_ins!$C:$C,MATCH('001_population_health_zone_zs'!$B2,[1]ratio_ins!$B:$B,0)) -> 8448.8871 | M2: =INDEX([1]ratio_ins!K:K,MATCH('001_population_health_zone_zs'!$B$2,[1]ratio_ins!$B:$B,0))*$G2*INDEX([1]ratio_ins!$C:$C,MATCH('001_population_health_zone_zs'!$B2,[1]ratio_ins!$B:$B,0)) -> 95821.916 | N2: =INDEX([1]ratio_ins!L:L,MATCH('001_population_health_zone_zs'!$B$2,[1]ratio_ins!$B:$B,0))*$G2*INDEX([1]ratio_ins!$C:$C,MATCH('001_population_health_zone_zs'!$B2,[1]ratio_ins!$B:$B,0)) -> 5632.5914 | O2: =INDEX([1]ratio_ins!M:M,MATCH('001_population_health_zone_zs'!$B$2,[1]ratio_ins!$B:$B,0))*$G2*INDEX([1]ratio_ins!$C:$C,MATCH('001_population_health_zone_zs'!$B2,[1]ratio_ins!$B:$B,0)) -> 12215.258 | P2: =INDEX([1]ratio_ins!N:N,MATCH('001_population_health_zone_zs'!$B$2,[1]ratio_ins!$B:$B,0))*$G2*INDEX([1]ratio_ins!$C:$C,MATCH('001_population_health_zone_zs'!$B2,[1]ratio_ins!$B:$B,0)) -> 11027.664 | Q2: =INDEX([1]ratio_ins!O:O,MATCH('001_population_health_zone_zs'!$B$2,[1]ratio_ins!$B:$B,0))*$G2*INDEX([1]ratio_ins!$C:$C,MATCH('001_population_health_zone_zs'!$B2,[1]ratio_ins!$B:$B,0)) -> 9840.0693 | R2: =INDEX([1]ratio_ins!P:P,MATCH('001_population_health_zone_zs'!$B$2,[1]ratio_ins!$B:$B,0))*$G2*INDEX([1]ratio_ins!$C:$C,MATCH('001_population_health_zone_zs'!$B2,[1]ratio_ins!$B:$B,0)) -> 9670.4129 | S2: =INDEX([1]ratio_ins!Q:Q,MATCH('001_population_health_zone_zs'!$B$2,[1]ratio_ins!$B:$B,0))*$G2*INDEX([1]ratio_ins!$C:$C,MATCH('001_population_health_zone_zs'!$B2,[1]ratio_ins!$B:$B,0)) -> 8143.5056 | T2: =INDEX([1]ratio_ins!R:R,MATCH('001_population_health_zone_zs'!$B$2,[1]ratio_ins!$B:$B,0))*$G2*INDEX([1]ratio_ins!$C:$C,MATCH('001_population_health_zone_zs'!$B2,[1]ratio_ins!$B:$B,0)) -> 5768.3165 | U2: =INDEX([1]ratio_ins!S:S,MATCH('001_population_health_zone_zs'!$B$2,[1]ratio_ins!$B:$B,0))*$G2*INDEX([1]ratio_ins!$C:$C,MATCH('001_population_health_zone_zs'!$B2,[1]ratio_ins!$B:$B,0)) -> 4580.7219 | V2: =INDEX([1]ratio_ins!T:T,MATCH('001_population_health_zone_zs'!$B$2,[1]ratio_ins!$B:$B,0))*$G2*INDEX([1]ratio_ins!$C:$C,MATCH('001_population_health_zone_zs'!$B2,[1]ratio_ins!$B:$B,0)) -> 2544.8455 | W2: =INDEX([1]ratio_ins!U:U,MATCH('001_population_health_zone_zs'!$B$2,[1]ratio_ins!$B:$B,0))*$G2*INDEX([1]ratio_ins!$C:$C,MATCH('001_population_health_zone_zs'!$B2,[1]ratio_ins!$B:$B,0)) -> 69423.385 | X2: =INDEX([1]ratio_ins!V:V,MATCH('001_population_health_zone_zs'!$B$2,[1]ratio_ins!$B:$B,0))*$G2*INDEX([1]ratio_ins!$C:$C,MATCH('001_population_health_zone_zs'!$B2,[1]ratio_ins!$B:$B,0)) -> 2035.8764 | Y2: =INDEX([1]ratio_ins!W:W,MATCH('001_population_health_zone_zs'!$B$2,[1]ratio_ins!$B:$B,0))*$G2*INDEX([1]ratio_ins!$C:$C,MATCH('001_population_health_zone_zs'!$B2,[1]ratio_ins!$B:$B,0)) -> 1357.2509 | Z2: =INDEX([1]ratio_ins!X:X,MATCH('001_population_health_zone_zs'!$B$2,[1]ratio_ins!$B:$B,0))*$G2*INDEX([1]ratio_ins!$C:$C,MATCH('001_population_health_zone_zs'!$B2,[1]ratio_ins!$B:$B,0)) -> 678.62547 | AA2: =INDEX([1]ratio_ins!Y:Y,MATCH('001_population_health_zone_zs'!$B$2,[1]ratio_ins!$B:$B,0))*$G2*INDEX([1]ratio_ins!$C:$C,MATCH('001_population_health_zone_zs'!$B2,[1]ratio_ins!$B:$B,0)) -> 339.31273 | AB2: =INDEX([1]ratio_ins!Z:Z,MATCH('001_population_health_zone_zs'!$B$2,[1]ratio_ins!$B:$B,0))*$G2*INDEX([1]ratio_ins!$C:$C,MATCH('001_population_health_zone_zs'!$B2,[1]ratio_ins!$B:$B,0)) -> 4411.0655 | AC2: =M2+W2+AB2 -> 169656.37 | AD2: =INDEX([1]ratio_ins!AA:AA,MATCH('001_population_health_zone_zs'!$B$2,[1]ratio_ins!$B:$B,0))*$G2*INDEX([1]ratio_ins!$D:$D,MATCH('001_population_health_zone_zs'!$B2,[1]ratio_ins!$B:$B,0)) -> 35202.853 | AE2: =INDEX([1]ratio_ins!AB:AB,MATCH('001_population_health_zone_zs'!$B$2,[1]ratio_ins!$B:$B,0))*$G2*INDEX([1]ratio_ins!$D:$D,MATCH('001_population_health_zone_zs'!$B2,[1]ratio_ins!$B:$B,0)) -> 29000.446 | AF2: =INDEX([1]ratio_ins!AC:AC,MATCH('001_population_health_zone_zs'!$B$2,[1]ratio_ins!$B:$B,0))*$G2*INDEX([1]ratio_ins!$D:$D,MATCH('001_population_health_zone_zs'!$B2,[1]ratio_ins!$B:$B,0)) -> 22965.671 | AG2: =INDEX([1]ratio_ins!AD:AD,MATCH('001_population_health_zone_zs'!$B$2,[1]ratio_ins!$B:$B,0))*$G2*INDEX([1]ratio_ins!$D:$D,MATCH('001_population_health_zone_zs'!$B2,[1]ratio_ins!$B:$B,0)) -> 13913.509 | AH2: =INDEX([1]ratio_ins!AE:AE,MATCH('001_population_health_zone_zs'!$B$2,[1]ratio_ins!$B:$B,0))*$G2*INDEX([1]ratio_ins!$D:$D,MATCH('001_population_health_zone_zs'!$B2,[1]ratio_ins!$B:$B,0)) -> 8348.1051 | AI2: =INDEX([1]ratio_ins!AF:AF,MATCH('001_population_health_zone_zs'!$B$2,[1]ratio_ins!$B:$B,0))*$G2*INDEX([1]ratio_ins!$D:$D,MATCH('001_population_health_zone_zs'!$B2,[1]ratio_ins!$B:$B,0)) -> 95517.074 | AJ2: =INDEX([1]ratio_ins!AG:AG,MATCH('001_population_health_zone_zs'!$B$2,[1]ratio_ins!$B:$B,0))*$G2*INDEX([1]ratio_ins!$D:$D,MATCH('001_population_health_zone_zs'!$B2,[1]ratio_ins!$B:$B,0)) -> 5565.4034 | AK2: =INDEX([1]ratio_ins!AH:AH,MATCH('001_population_health_zone_zs'!$B$2,[1]ratio_ins!$B:$B,0))*$G2*INDEX([1]ratio_ins!$D:$D,MATCH('001_population_health_zone_zs'!$B2,[1]ratio_ins!$B:$B,0)) -> 12404.815 | AL2: =INDEX([1]ratio_ins!AI:AI,MATCH('001_population_health_zone_zs'!$B$2,[1]ratio_ins!$B:$B,0))*$G2*INDEX([1]ratio_ins!$D:$D,MATCH('001_population_health_zone_zs'!$B2,[1]ratio_ins!$B:$B,0)) -> 11734.284 | AM2: =INDEX([1]ratio_ins!AJ:AJ,MATCH('001_population_health_zone_zs'!$B$2,[1]ratio_ins!$B:$B,0))*$G2*INDEX([1]ratio_ins!$D:$D,MATCH('001_population_health_zone_zs'!$B2,[1]ratio_ins!$B:$B,0)) -> 10728.489 | AN2: =INDEX([1]ratio_ins!AK:AK,MATCH('001_population_health_zone_zs'!$B$2,[1]ratio_ins!$B:$B,0))*$G2*INDEX([1]ratio_ins!$D:$D,MATCH('001_population_health_zone_zs'!$B2,[1]ratio_ins!$B:$B,0)) -> 10057.958 | AO2: =INDEX([1]ratio_ins!AL:AL,MATCH('001_population_health_zone_zs'!$B$2,[1]ratio_ins!$B:$B,0))*$G2*INDEX([1]ratio_ins!$D:$D,MATCH('001_population_health_zone_zs'!$B2,[1]ratio_ins!$B:$B,0)) -> 7543.4685 | AP2: =INDEX([1]ratio_ins!AM:AM,MATCH('001_population_health_zone_zs'!$B$2,[1]ratio_ins!$B:$B,0))*$G2*INDEX([1]ratio_ins!$D:$D,MATCH('001_population_health_zone_zs'!$B2,[1]ratio_ins!$B:$B,0)) -> 4861.3464 | AQ2: =INDEX([1]ratio_ins!AN:AN,MATCH('001_population_health_zone_zs'!$B$2,[1]ratio_ins!$B:$B,0))*$G2*INDEX([1]ratio_ins!$D:$D,MATCH('001_population_health_zone_zs'!$B2,[1]ratio_ins!$B:$B,0)) -> 3855.5506 | AR2: =INDEX([1]ratio_ins!AO:AO,MATCH('001_population_health_zone_zs'!$B$2,[1]ratio_ins!$B:$B,0))*$G2*INDEX([1]ratio_ins!$D:$D,MATCH('001_population_health_zone_zs'!$B2,[1]ratio_ins!$B:$B,0)) -> 1843.959 | AS2: =INDEX([1]ratio_ins!AP:AP,MATCH('001_population_health_zone_zs'!$B$2,[1]ratio_ins!$B:$B,0))*$G2*INDEX([1]ratio_ins!$D:$D,MATCH('001_population_health_zone_zs'!$B2,[1]ratio_ins!$B:$B,0)) -> 68595.273 | AT2: =INDEX([1]ratio_ins!AQ:AQ,MATCH('001_population_health_zone_zs'!$B$2,[1]ratio_ins!$B:$B,0))*$G2*INDEX([1]ratio_ins!$D:$D,MATCH('001_population_health_zone_zs'!$B2,[1]ratio_ins!$B:$B,0)) -> 1676.3263 | AU2: =INDEX([1]ratio_ins!AR:AR,MATCH('001_population_health_zone_zs'!$B$2,[1]ratio_ins!$B:$B,0))*$G2*INDEX([1]ratio_ins!$D:$D,MATCH('001_population_health_zone_zs'!$B2,[1]ratio_ins!$B:$B,0)) -> 1005.7958 | AV2: =INDEX([1]ratio_ins!AS:AS,MATCH('001_population_health_zone_zs'!$B$2,[1]ratio_ins!$B:$B,0))*$G2*INDEX([1]ratio_ins!$D:$D,MATCH('001_population_health_zone_zs'!$B2,[1]ratio_ins!$B:$B,0)) -> 502.8979 | AW2: =INDEX([1]ratio_ins!AT:AT,MATCH('001_population_health_zone_zs'!$B$2,[1]ratio_ins!$B:$B,0))*$G2*INDEX([1]ratio_ins!$D:$D,MATCH('001_population_health_zone_zs'!$B2,[1]ratio_ins!$B:$B,0)) -> 335.26527 | AX2: =INDEX([1]ratio_ins!AU:AU,MATCH('001_population_health_zone_zs'!$B$2,[1]ratio_ins!$B:$B,0))*$G2*INDEX([1]ratio_ins!$D:$D,MATCH('001_population_health_zone_zs'!$B2,[1]ratio_ins!$B:$B,0)) -> 3520.2853 | AY2: =AI2+AS2+AX2 -> 167632.63 | AZ2: =AC2+AY2 -> 337289 | BA2: 333386.66 | BB2: =SUM(AH2,AJ2,AK2:AP2) -> 71243.869 | BC2: =BB2/G2 -> 0.211225 | BD2: =SUM(L2,N2:T2) -> 70746.705
A3: Kinshasa | B3: CD10 | C3: Kinshasa | D3: CD1000 | E3: Barumbu | F3: CD1000ZS02 | G3: 281886 | H3: =INDEX([1]ratio_ins!F:F,MATCH('001_population_health_zone_zs'!$B$2,[1]ratio_ins!$B:$B,0))*$G3*INDEX([1]ratio_ins!$C:$C,MATCH('001_population_health_zone_zs'!$B3,[1]ratio_ins!$B:$B,0)) -> 29633.83 | I3: =INDEX([1]ratio_ins!G:G,MATCH('001_population_health_zone_zs'!$B$2,[1]ratio_ins!$B:$B,0))*$G3*INDEX([1]ratio_ins!$C:$C,MATCH('001_population_health_zone_zs'!$B3,[1]ratio_ins!$B:$B,0)) -> 24245.861 | J3: =INDEX([1]ratio_ins!H:H,MATCH('001_population_health_zone_zs'!$B$2,[1]ratio_ins!$B:$B,0))*$G3*INDEX([1]ratio_ins!$C:$C,MATCH('001_population_health_zone_zs'!$B3,[1]ratio_ins!$B:$B,0)) -> 19141.469 | K3: =INDEX([1]ratio_ins!I:I,MATCH('001_population_health_zone_zs'!$B$2,[1]ratio_ins!$B:$B,0))*$G3*INDEX([1]ratio_ins!$C:$C,MATCH('001_population_health_zone_zs'!$B3,[1]ratio_ins!$B:$B,0)) -> 11768.459 | L3: =INDEX([1]ratio_ins!J:J,MATCH('001_population_health_zone_zs'!$B$2,[1]ratio_ins!$B:$B,0))*$G3*INDEX([1]ratio_ins!$C:$C,MATCH('001_population_health_zone_zs'!$B3,[1]ratio_ins!$B:$B,0)) -> 7061.0752 | M3: =INDEX([1]ratio_ins!K:K,MATCH('001_population_health_zone_zs'!$B$2,[1]ratio_ins!$B:$B,0))*$G3*INDEX([1]ratio_ins!$C:$C,MATCH('001_population_health_zone_zs'!$B3,[1]ratio_ins!$B:$B,0)) -> 80082.234 | N3: =INDEX([1]ratio_ins!L:L,MATCH('001_population_health_zone_zs'!$B$2,[1]ratio_ins!$B:$B,0))*$G3*INDEX([1]ratio_ins!$C:$C,MATCH('001_population_health_zone_zs'!$B3,[1]ratio_ins!$B:$B,0)) -> 4707.3834 | O3: =INDEX([1]ratio_ins!M:M,MATCH('001_population_health_zone_zs'!$B$2,[1]ratio_ins!$B:$B,0))*$G3*INDEX([1]ratio_ins!$C:$C,MATCH('001_population_health_zone_zs'!$B3,[1]ratio_ins!$B:$B,0)) -> 10208.783 | P3: =INDEX([1]ratio_ins!N:N,MATCH('001_population_health_zone_zs'!$B$2,[1]ratio_ins!$B:$B,0))*$G3*INDEX([1]ratio_ins!$C:$C,MATCH('001_population_health_zone_zs'!$B3,[1]ratio_ins!$B:$B,0)) -> 9216.2628 | Q3: =INDEX([1]ratio_ins!O:O,MATCH('001_population_health_zone_zs'!$B$2,[1]ratio_ins!$B:$B,0))*$G3*INDEX([1]ratio_ins!$C:$C,MATCH('001_population_health_zone_zs'!$B3,[1]ratio_ins!$B:$B,0)) -> 8223.7422 | R3: =INDEX([1]ratio_ins!P:P,MATCH('001_population_health_zone_zs'!$B$2,[1]ratio_ins!$B:$B,0))*$G3*INDEX([1]ratio_ins!$C:$C,MATCH('001_population_health_zone_zs'!$B3,[1]ratio_ins!$B:$B,0)) -> 8081.9535 | S3: =INDEX([1]ratio_ins!Q:Q,MATCH('001_population_health_zone_zs'!$B$2,[1]ratio_ins!$B:$B,0))*$G3*INDEX([1]ratio_ins!$C:$C,MATCH('001_population_health_zone_zs'!$B3,[1]ratio_ins!$B:$B,0)) -> 6805.8556 | T3: =INDEX([1]ratio_ins!R:R,MATCH('001_population_health_zone_zs'!$B$2,[1]ratio_ins!$B:$B,0))*$G3*INDEX([1]ratio_ins!$C:$C,MATCH('001_population_health_zone_zs'!$B3,[1]ratio_ins!$B:$B,0)) -> 4820.8144 | U3: =INDEX([1]ratio_ins!S:S,MATCH('001_population_health_zone_zs'!$B$2,[1]ratio_ins!$B:$B,0))*$G3*INDEX([1]ratio_ins!$C:$C,MATCH('001_population_health_zone_zs'!$B3,[1]ratio_ins!$B:$B,0)) -> 3828.2938 | V3: =INDEX([1]ratio_ins!T:T,MATCH('001_population_health_zone_zs'!$B$2,[1]ratio_ins!$B:$B,0))*$G3*INDEX([1]ratio_ins!$C:$C,MATCH('001_population_health_zone_zs'!$B3,[1]ratio_ins!$B:$B,0)) -> 2126.8299 | W3: =INDEX([1]ratio_ins!U:U,MATCH('001_population_health_zone_zs'!$B$2,[1]ratio_ins!$B:$B,0))*$G3*INDEX([1]ratio_ins!$C:$C,MATCH('001_population_health_zone_zs'!$B3,[1]ratio_ins!$B:$B,0)) -> 58019.919 | X3: =INDEX([1]ratio_ins!V:V,MATCH('001_population_health_zone_zs'!$B$2,[1]ratio_ins!$B:$B,0))*$G3*INDEX([1]ratio_ins!$C:$C,MATCH('001_population_health_zone_zs'!$B3,[1]ratio_ins!$B:$B,0)) -> 1701.4639 | Y3: =INDEX([1]ratio_ins!W:W,MATCH('001_population_health_zone_zs'!$B$2,[1]ratio_ins!$B:$B,0))*$G3*INDEX([1]ratio_ins!$C:$C,MATCH('001_population_health_zone_zs'!$B3,[1]ratio_ins!$B:$B,0)) -> 1134.3093 | Z3: =INDEX([1]ratio_ins!X:X,MATCH('001_population_health_zone_zs'!$B$2,[1]ratio_ins!$B:$B,0))*$G3*INDEX([1]ratio_ins!$C:$C,MATCH('001_population_health_zone_zs'!$B3,[1]ratio_ins!$B:$B,0)) -> 567.15463 | AA3: =INDEX([1]ratio_ins!Y:Y,MATCH('001_population_health_zone_zs'!$B$2,[1]ratio_ins!$B:$B,0))*$G3*INDEX([1]ratio_ins!$C:$C,MATCH('001_population_health_zone_zs'!$B3,[1]ratio_ins!$B:$B,0)) -> 283.57732 | AB3: =INDEX([1]ratio_ins!Z:Z,MATCH('001_population_health_zone_zs'!$B$2,[1]ratio_ins!$B:$B,0))*$G3*INDEX([1]ratio_ins!$C:$C,MATCH('001_population_health_zone_zs'!$B3,[1]ratio_ins!$B:$B,0)) -> 3686.5051 | AC3: =M3+W3+AB3 -> 141788.66 | AD3: =INDEX([1]ratio_ins!AA:AA,MATCH('001_population_health_zone_zs'!$B$2,[1]ratio_ins!$B:$B,0))*$G3*INDEX([1]ratio_ins!$D:$D,MATCH('001_population_health_zone_zs'!$B3,[1]ratio_ins!$B:$B,0)) -> 29420.442 | AE3: =INDEX([1]ratio_ins!AB:AB,MATCH('001_population_health_zone_zs'!$B$2,[1]ratio_ins!$B:$B,0))*$G3*INDEX([1]ratio_ins!$D:$D,MATCH('001_population_health_zone_zs'!$B3,[1]ratio_ins!$B:$B,0)) -> 24236.84 | AF3: =INDEX([1]ratio_ins!AC:AC,MATCH('001_population_health_zone_zs'!$B$2,[1]ratio_ins!$B:$B,0))*$G3*INDEX([1]ratio_ins!$D:$D,MATCH('001_population_health_zone_zs'!$B3,[1]ratio_ins!$B:$B,0)) -> 19193.336 | AG3: =INDEX([1]ratio_ins!AD:AD,MATCH('001_population_health_zone_zs'!$B$2,[1]ratio_ins!$B:$B,0))*$G3*INDEX([1]ratio_ins!$D:$D,MATCH('001_population_health_zone_zs'!$B3,[1]ratio_ins!$B:$B,0)) -> 11628.079 | AH3: =INDEX([1]ratio_ins!AE:AE,MATCH('001_population_health_zone_zs'!$B$2,[1]ratio_ins!$B:$B,0))*$G3*INDEX([1]ratio_ins!$D:$D,MATCH('001_population_health_zone_zs'!$B3,[1]ratio_ins!$B:$B,0)) -> 6976.8476 | AI3: =INDEX([1]ratio_ins!AF:AF,MATCH('001_population_health_zone_zs'!$B$2,[1]ratio_ins!$B:$B,0))*$G3*INDEX([1]ratio_ins!$D:$D,MATCH('001_population_health_zone_zs'!$B3,[1]ratio_ins!$B:$B,0)) -> 79827.465 | AJ3: =INDEX([1]ratio_ins!AG:AG,MATCH('001_population_health_zone_zs'!$B$2,[1]ratio_ins!$B:$B,0))*$G3*INDEX([1]ratio_ins!$D:$D,MATCH('001_population_health_zone_zs'!$B3,[1]ratio_ins!$B:$B,0)) -> 4651.2318 | AK3: =INDEX([1]ratio_ins!AH:AH,MATCH('001_population_health_zone_zs'!$B$2,[1]ratio_ins!$B:$B,0))*$G3*INDEX([1]ratio_ins!$D:$D,MATCH('001_population_health_zone_zs'!$B3,[1]ratio_ins!$B:$B,0)) -> 10367.203 | AL3: =INDEX([1]ratio_ins!AI:AI,MATCH('001_population_health_zone_zs'!$B$2,[1]ratio_ins!$B:$B,0))*$G3*INDEX([1]ratio_ins!$D:$D,MATCH('001_population_health_zone_zs'!$B3,[1]ratio_ins!$B:$B,0)) -> 9806.8139 | AM3: =INDEX([1]ratio_ins!AJ:AJ,MATCH('001_population_health_zone_zs'!$B$2,[1]ratio_ins!$B:$B,0))*$G3*INDEX([1]ratio_ins!$D:$D,MATCH('001_population_health_zone_zs'!$B3,[1]ratio_ins!$B:$B,0)) -> 8966.2299 | AN3: =INDEX([1]ratio_ins!AK:AK,MATCH('001_population_health_zone_zs'!$B$2,[1]ratio_ins!$B:$B,0))*$G3*INDEX([1]ratio_ins!$D:$D,MATCH('001_population_health_zone_zs'!$B3,[1]ratio_ins!$B:$B,0)) -> 8405.8405 | AO3: =INDEX([1]ratio_ins!AL:AL,MATCH('001_population_health_zone_zs'!$B$2,[1]ratio_ins!$B:$B,0))*$G3*INDEX([1]ratio_ins!$D:$D,MATCH('001_population_health_zone_zs'!$B3,[1]ratio_ins!$B:$B,0)) -> 6304.3804 | AP3: =INDEX([1]ratio_ins!AM:AM,MATCH('001_population_health_zone_zs'!$B$2,[1]ratio_ins!$B:$B,0))*$G3*INDEX([1]ratio_ins!$D:$D,MATCH('001_population_health_zone_zs'!$B3,[1]ratio_ins!$B:$B,0)) -> 4062.8229 | AQ3: =INDEX([1]ratio_ins!AN:AN,MATCH('001_population_health_zone_zs'!$B$2,[1]ratio_ins!$B:$B,0))*$G3*INDEX([1]ratio_ins!$D:$D,MATCH('001_population_health_zone_zs'!$B3,[1]ratio_ins!$B:$B,0)) -> 3222.2389 | AR3: =INDEX([1]ratio_ins!AO:AO,MATCH('001_population_health_zone_zs'!$B$2,[1]ratio_ins!$B:$B,0))*$G3*INDEX([1]ratio_ins!$D:$D,MATCH('001_population_health_zone_zs'!$B3,[1]ratio_ins!$B:$B,0)) -> 1541.0708 | AS3: =INDEX([1]ratio_ins!AP:AP,MATCH('001_population_health_zone_zs'!$B$2,[1]ratio_ins!$B:$B,0))*$G3*INDEX([1]ratio_ins!$D:$D,MATCH('001_population_health_zone_zs'!$B3,[1]ratio_ins!$B:$B,0)) -> 57327.832 | AT3: =INDEX([1]ratio_ins!AQ:AQ,MATCH('001_population_health_zone_zs'!$B$2,[1]ratio_ins!$B:$B,0))*$G3*INDEX([1]ratio_ins!$D:$D,MATCH('001_population_health_zone_zs'!$B3,[1]ratio_ins!$B:$B,0)) -> 1400.9734 | AU3: =INDEX([1]ratio_ins!AR:AR,MATCH('001_population_health_zone_zs'!$B$2,[1]ratio_ins!$B:$B,0))*$G3*INDEX([1]ratio_ins!$D:$D,MATCH('001_population_health_zone_zs'!$B3,[1]ratio_ins!$B:$B,0)) -> 840.58405 | AV3: =INDEX([1]ratio_ins!AS:AS,MATCH('001_population_health_zone_zs'!$B$2,[1]ratio_ins!$B:$B,0))*$G3*INDEX([1]ratio_ins!$D:$D,MATCH('001_population_health_zone_zs'!$B3,[1]ratio_ins!$B:$B,0)) -> 420.29203 | AW3: =INDEX([1]ratio_ins!AT:AT,MATCH('001_population_health_zone_zs'!$B$2,[1]ratio_ins!$B:$B,0))*$G3*INDEX([1]ratio_ins!$D:$D,MATCH('001_population_health_zone_zs'!$B3,[1]ratio_ins!$B:$B,0)) -> 280.19468 | AX3: =INDEX([1]ratio_ins!AU:AU,MATCH('001_population_health_zone_zs'!$B$2,[1]ratio_ins!$B:$B,0))*$G3*INDEX([1]ratio_ins!$D:$D,MATCH('001_population_health_zone_zs'!$B3,[1]ratio_ins!$B:$B,0)) -> 2942.0442 | AY3: =AI3+AS3+AX3 -> 140097.34 | AZ3: =AC3+AY3 -> 281886 | BA3: 278624.9 | BB3: =SUM(AH3,AJ3,AK3:AP3) -> 59541.37 | BC3: =BB3/G3 -> 0.211225 | BD3: =SUM(L3,N3:T3) -> 59125.87
A4: Kinshasa | B4: CD10 | C4: Kinshasa | D4: CD1000 | E4: Binza Meteo | F4: CD1000ZS03 | G4: 745289 | H4: =INDEX([1]ratio_ins!F:F,MATCH('001_population_health_zone_zs'!$B$2,[1]ratio_ins!$B:$B,0))*$G4*INDEX([1]ratio_ins!$C:$C,MATCH('001_population_health_zone_zs'!$B4,[1]ratio_ins!$B:$B,0)) -> 78349.997 | I4: =INDEX([1]ratio_ins!G:G,MATCH('001_population_health_zone_zs'!$B$2,[1]ratio_ins!$B:$B,0))*$G4*INDEX([1]ratio_ins!$C:$C,MATCH('001_population_health_zone_zs'!$B4,[1]ratio_ins!$B:$B,0)) -> 64104.543 | J4: =INDEX([1]ratio_ins!H:H,MATCH('001_population_health_zone_zs'!$B$2,[1]ratio_ins!$B:$B,0))*$G4*INDEX([1]ratio_ins!$C:$C,MATCH('001_population_health_zone_zs'!$B4,[1]ratio_ins!$B:$B,0)) -> 50608.85 | K4: =INDEX([1]ratio_ins!I:I,MATCH('001_population_health_zone_zs'!$B$2,[1]ratio_ins!$B:$B,0))*$G4*INDEX([1]ratio_ins!$C:$C,MATCH('001_population_health_zone_zs'!$B4,[1]ratio_ins!$B:$B,0)) -> 31115.07 | L4: =INDEX([1]ratio_ins!J:J,MATCH('001_population_health_zone_zs'!$B$2,[1]ratio_ins!$B:$B,0))*$G4*INDEX([1]ratio_ins!$C:$C,MATCH('001_population_health_zone_zs'!$B4,[1]ratio_ins!$B:$B,0)) -> 18669.042 | M4: =INDEX([1]ratio_ins!K:K,MATCH('001_population_health_zone_zs'!$B$2,[1]ratio_ins!$B:$B,0))*$G4*INDEX([1]ratio_ins!$C:$C,MATCH('001_population_health_zone_zs'!$B4,[1]ratio_ins!$B:$B,0)) -> 211732.43 | N4: =INDEX([1]ratio_ins!L:L,MATCH('001_population_health_zone_zs'!$B$2,[1]ratio_ins!$B:$B,0))*$G4*INDEX([1]ratio_ins!$C:$C,MATCH('001_population_health_zone_zs'!$B4,[1]ratio_ins!$B:$B,0)) -> 12446.028 | O4: =INDEX([1]ratio_ins!M:M,MATCH('001_population_health_zone_zs'!$B$2,[1]ratio_ins!$B:$B,0))*$G4*INDEX([1]ratio_ins!$C:$C,MATCH('001_population_health_zone_zs'!$B4,[1]ratio_ins!$B:$B,0)) -> 26991.386 | P4: =INDEX([1]ratio_ins!N:N,MATCH('001_population_health_zone_zs'!$B$2,[1]ratio_ins!$B:$B,0))*$G4*INDEX([1]ratio_ins!$C:$C,MATCH('001_population_health_zone_zs'!$B4,[1]ratio_ins!$B:$B,0)) -> 24367.224 | Q4: =INDEX([1]ratio_ins!O:O,MATCH('001_population_health_zone_zs'!$B$2,[1]ratio_ins!$B:$B,0))*$G4*INDEX([1]ratio_ins!$C:$C,MATCH('001_population_health_zone_zs'!$B4,[1]ratio_ins!$B:$B,0)) -> 21743.061 | R4: =INDEX([1]ratio_ins!P:P,MATCH('001_population_health_zone_zs'!$B$2,[1]ratio_ins!$B:$B,0))*$G4*INDEX([1]ratio_ins!$C:$C,MATCH('001_population_health_zone_zs'!$B4,[1]ratio_ins!$B:$B,0)) -> 21368.181 | S4: =INDEX([1]ratio_ins!Q:Q,MATCH('001_population_health_zone_zs'!$B$2,[1]ratio_ins!$B:$B,0))*$G4*INDEX([1]ratio_ins!$C:$C,MATCH('001_population_health_zone_zs'!$B4,[1]ratio_ins!$B:$B,0)) -> 17994.258 | T4: =INDEX([1]ratio_ins!R:R,MATCH('001_population_health_zone_zs'!$B$2,[1]ratio_ins!$B:$B,0))*$G4*INDEX([1]ratio_ins!$C:$C,MATCH('001_population_health_zone_zs'!$B4,[1]ratio_ins!$B:$B,0)) -> 12745.932 | U4: =INDEX([1]ratio_ins!S:S,MATCH('001_population_health_zone_zs'!$B$2,[1]ratio_ins!$B:$B,0))*$G4*INDEX([1]ratio_ins!$C:$C,MATCH('001_population_health_zone_zs'!$B4,[1]ratio_ins!$B:$B,0)) -> 10121.77 | V4: =INDEX([1]ratio_ins!T:T,MATCH('001_population_health_zone_zs'!$B$2,[1]ratio_ins!$B:$B,0))*$G4*INDEX([1]ratio_ins!$C:$C,MATCH('001_population_health_zone_zs'!$B4,[1]ratio_ins!$B:$B,0)) -> 5623.2055 | W4: =INDEX([1]ratio_ins!U:U,MATCH('001_population_health_zone_zs'!$B$2,[1]ratio_ins!$B:$B,0))*$G4*INDEX([1]ratio_ins!$C:$C,MATCH('001_population_health_zone_zs'!$B4,[1]ratio_ins!$B:$B,0)) -> 153401.05 | X4: =INDEX([1]ratio_ins!V:V,MATCH('001_population_health_zone_zs'!$B$2,[1]ratio_ins!$B:$B,0))*$G4*INDEX([1]ratio_ins!$C:$C,MATCH('001_population_health_zone_zs'!$B4,[1]ratio_ins!$B:$B,0)) -> 4498.5644 | Y4: =INDEX([1]ratio_ins!W:W,MATCH('001_population_health_zone_zs'!$B$2,[1]ratio_ins!$B:$B,0))*$G4*INDEX([1]ratio_ins!$C:$C,MATCH('001_population_health_zone_zs'!$B4,[1]ratio_ins!$B:$B,0)) -> 2999.0429 | Z4: =INDEX([1]ratio_ins!X:X,MATCH('001_population_health_zone_zs'!$B$2,[1]ratio_ins!$B:$B,0))*$G4*INDEX([1]ratio_ins!$C:$C,MATCH('001_population_health_zone_zs'!$B4,[1]ratio_ins!$B:$B,0)) -> 1499.5215 | AA4: =INDEX([1]ratio_ins!Y:Y,MATCH('001_population_health_zone_zs'!$B$2,[1]ratio_ins!$B:$B,0))*$G4*INDEX([1]ratio_ins!$C:$C,MATCH('001_population_health_zone_zs'!$B4,[1]ratio_ins!$B:$B,0)) -> 749.76073 | AB4: =INDEX([1]ratio_ins!Z:Z,MATCH('001_population_health_zone_zs'!$B$2,[1]ratio_ins!$B:$B,0))*$G4*INDEX([1]ratio_ins!$C:$C,MATCH('001_population_health_zone_zs'!$B4,[1]ratio_ins!$B:$B,0)) -> 9746.8895 | AC4: =M4+W4+AB4 -> 374880.37 | AD4: =INDEX([1]ratio_ins!AA:AA,MATCH('001_population_health_zone_zs'!$B$2,[1]ratio_ins!$B:$B,0))*$G4*INDEX([1]ratio_ins!$D:$D,MATCH('001_population_health_zone_zs'!$B4,[1]ratio_ins!$B:$B,0)) -> 77785.813 | AE4: =INDEX([1]ratio_ins!AB:AB,MATCH('001_population_health_zone_zs'!$B$2,[1]ratio_ins!$B:$B,0))*$G4*INDEX([1]ratio_ins!$D:$D,MATCH('001_population_health_zone_zs'!$B4,[1]ratio_ins!$B:$B,0)) -> 64080.694 | AF4: =INDEX([1]ratio_ins!AC:AC,MATCH('001_population_health_zone_zs'!$B$2,[1]ratio_ins!$B:$B,0))*$G4*INDEX([1]ratio_ins!$D:$D,MATCH('001_population_health_zone_zs'!$B4,[1]ratio_ins!$B:$B,0)) -> 50745.983 | AG4: =INDEX([1]ratio_ins!AD:AD,MATCH('001_population_health_zone_zs'!$B$2,[1]ratio_ins!$B:$B,0))*$G4*INDEX([1]ratio_ins!$D:$D,MATCH('001_population_health_zone_zs'!$B4,[1]ratio_ins!$B:$B,0)) -> 30743.917 | AH4: =INDEX([1]ratio_ins!AE:AE,MATCH('001_population_health_zone_zs'!$B$2,[1]ratio_ins!$B:$B,0))*$G4*INDEX([1]ratio_ins!$D:$D,MATCH('001_population_health_zone_zs'!$B4,[1]ratio_ins!$B:$B,0)) -> 18446.35 | AI4: =INDEX([1]ratio_ins!AF:AF,MATCH('001_population_health_zone_zs'!$B$2,[1]ratio_ins!$B:$B,0))*$G4*INDEX([1]ratio_ins!$D:$D,MATCH('001_population_health_zone_zs'!$B4,[1]ratio_ins!$B:$B,0)) -> 211058.84 | AJ4: =INDEX([1]ratio_ins!AG:AG,MATCH('001_population_health_zone_zs'!$B$2,[1]ratio_ins!$B:$B,0))*$G4*INDEX([1]ratio_ins!$D:$D,MATCH('001_population_health_zone_zs'!$B4,[1]ratio_ins!$B:$B,0)) -> 12297.567 | AK4: =INDEX([1]ratio_ins!AH:AH,MATCH('001_population_health_zone_zs'!$B$2,[1]ratio_ins!$B:$B,0))*$G4*INDEX([1]ratio_ins!$D:$D,MATCH('001_population_health_zone_zs'!$B4,[1]ratio_ins!$B:$B,0)) -> 27410.239 | AL4: =INDEX([1]ratio_ins!AI:AI,MATCH('001_population_health_zone_zs'!$B$2,[1]ratio_ins!$B:$B,0))*$G4*INDEX([1]ratio_ins!$D:$D,MATCH('001_population_health_zone_zs'!$B4,[1]ratio_ins!$B:$B,0)) -> 25928.604 | AM4: =INDEX([1]ratio_ins!AJ:AJ,MATCH('001_population_health_zone_zs'!$B$2,[1]ratio_ins!$B:$B,0))*$G4*INDEX([1]ratio_ins!$D:$D,MATCH('001_population_health_zone_zs'!$B4,[1]ratio_ins!$B:$B,0)) -> 23706.153 | AN4: =INDEX([1]ratio_ins!AK:AK,MATCH('001_population_health_zone_zs'!$B$2,[1]ratio_ins!$B:$B,0))*$G4*INDEX([1]ratio_ins!$D:$D,MATCH('001_population_health_zone_zs'!$B4,[1]ratio_ins!$B:$B,0)) -> 22224.518 | AO4: =INDEX([1]ratio_ins!AL:AL,MATCH('001_population_health_zone_zs'!$B$2,[1]ratio_ins!$B:$B,0))*$G4*INDEX([1]ratio_ins!$D:$D,MATCH('001_population_health_zone_zs'!$B4,[1]ratio_ins!$B:$B,0)) -> 16668.388 | AP4: =INDEX([1]ratio_ins!AM:AM,MATCH('001_population_health_zone_zs'!$B$2,[1]ratio_ins!$B:$B,0))*$G4*INDEX([1]ratio_ins!$D:$D,MATCH('001_population_health_zone_zs'!$B4,[1]ratio_ins!$B:$B,0)) -> 10741.85 | AQ4: =INDEX([1]ratio_ins!AN:AN,MATCH('001_population_health_zone_zs'!$B$2,[1]ratio_ins!$B:$B,0))*$G4*INDEX([1]ratio_ins!$D:$D,MATCH('001_population_health_zone_zs'!$B4,[1]ratio_ins!$B:$B,0)) -> 8519.3986 | AR4: =INDEX([1]ratio_ins!AO:AO,MATCH('001_population_health_zone_zs'!$B$2,[1]ratio_ins!$B:$B,0))*$G4*INDEX([1]ratio_ins!$D:$D,MATCH('001_population_health_zone_zs'!$B4,[1]ratio_ins!$B:$B,0)) -> 4074.495 | AS4: =INDEX([1]ratio_ins!AP:AP,MATCH('001_population_health_zone_zs'!$B$2,[1]ratio_ins!$B:$B,0))*$G4*INDEX([1]ratio_ins!$D:$D,MATCH('001_population_health_zone_zs'!$B4,[1]ratio_ins!$B:$B,0)) -> 151571.21 | AT4: =INDEX([1]ratio_ins!AQ:AQ,MATCH('001_population_health_zone_zs'!$B$2,[1]ratio_ins!$B:$B,0))*$G4*INDEX([1]ratio_ins!$D:$D,MATCH('001_population_health_zone_zs'!$B4,[1]ratio_ins!$B:$B,0)) -> 3704.0863 | AU4: =INDEX([1]ratio_ins!AR:AR,MATCH('001_population_health_zone_zs'!$B$2,[1]ratio_ins!$B:$B,0))*$G4*INDEX([1]ratio_ins!$D:$D,MATCH('001_population_health_zone_zs'!$B4,[1]ratio_ins!$B:$B,0)) -> 2222.4518 | AV4: =INDEX([1]ratio_ins!AS:AS,MATCH('001_population_health_zone_zs'!$B$2,[1]ratio_ins!$B:$B,0))*$G4*INDEX([1]ratio_ins!$D:$D,MATCH('001_population_health_zone_zs'!$B4,[1]ratio_ins!$B:$B,0)) -> 1111.2259 | AW4: =INDEX([1]ratio_ins!AT:AT,MATCH('001_population_health_zone_zs'!$B$2,[1]ratio_ins!$B:$B,0))*$G4*INDEX([1]ratio_ins!$D:$D,MATCH('001_population_health_zone_zs'!$B4,[1]ratio_ins!$B:$B,0)) -> 740.81727 | AX4: =INDEX([1]ratio_ins!AU:AU,MATCH('001_population_health_zone_zs'!$B$2,[1]ratio_ins!$B:$B,0))*$G4*INDEX([1]ratio_ins!$D:$D,MATCH('001_population_health_zone_zs'!$B4,[1]ratio_ins!$B:$B,0)) -> 7778.5813 | AY4: =AI4+AS4+AX4 -> 370408.63 | AZ4: =AC4+AY4 -> 745289 | BA4: 736666.73 | BB4: =SUM(AH4,AJ4,AK4:AP4) -> 157423.67 | BC4: =BB4/G4 -> 0.211225 | BD4: =SUM(L4,N4:T4) -> 156325.11
A5: Kinshasa | B5: CD10 | C5: Kinshasa | D5: CD1000 | E5: Binza Ozone | F5: CD1000ZS04 | G5: 694614 | H5: =INDEX([1]ratio_ins!F:F,MATCH('001_population_health_zone_zs'!$B$2,[1]ratio_ins!$B:$B,0))*$G5*INDEX([1]ratio_ins!$C:$C,MATCH('001_population_health_zone_zs'!$B5,[1]ratio_ins!$B:$B,0)) -> 73022.686 | I5: =INDEX([1]ratio_ins!G:G,MATCH('001_population_health_zone_zs'!$B$2,[1]ratio_ins!$B:$B,0))*$G5*INDEX([1]ratio_ins!$C:$C,MATCH('001_population_health_zone_zs'!$B5,[1]ratio_ins!$B:$B,0)) -> 59745.834 | J5: =INDEX([1]ratio_ins!H:H,MATCH('001_population_health_zone_zs'!$B$2,[1]ratio_ins!$B:$B,0))*$G5*INDEX([1]ratio_ins!$C:$C,MATCH('001_population_health_zone_zs'!$B5,[1]ratio_ins!$B:$B,0)) -> 47167.764 | K5: =INDEX([1]ratio_ins!I:I,MATCH('001_population_health_zone_zs'!$B$2,[1]ratio_ins!$B:$B,0))*$G5*INDEX([1]ratio_ins!$C:$C,MATCH('001_population_health_zone_zs'!$B5,[1]ratio_ins!$B:$B,0)) -> 28999.44 | L5: =INDEX([1]ratio_ins!J:J,MATCH('001_population_health_zone_zs'!$B$2,[1]ratio_ins!$B:$B,0))*$G5*INDEX([1]ratio_ins!$C:$C,MATCH('001_population_health_zone_zs'!$B5,[1]ratio_ins!$B:$B,0)) -> 17399.664 | M5: =INDEX([1]ratio_ins!K:K,MATCH('001_population_health_zone_zs'!$B$2,[1]ratio_ins!$B:$B,0))*$G5*INDEX([1]ratio_ins!$C:$C,MATCH('001_population_health_zone_zs'!$B5,[1]ratio_ins!$B:$B,0)) -> 197335.95 | N5: =INDEX([1]ratio_ins!L:L,MATCH('001_population_health_zone_zs'!$B$2,[1]ratio_ins!$B:$B,0))*$G5*INDEX([1]ratio_ins!$C:$C,MATCH('001_population_health_zone_zs'!$B5,[1]ratio_ins!$B:$B,0)) -> 11599.776 | O5: =INDEX([1]ratio_ins!M:M,MATCH('001_population_health_zone_zs'!$B$2,[1]ratio_ins!$B:$B,0))*$G5*INDEX([1]ratio_ins!$C:$C,MATCH('001_population_health_zone_zs'!$B5,[1]ratio_ins!$B:$B,0)) -> 25156.141 | P5: =INDEX([1]ratio_ins!N:N,MATCH('001_population_health_zone_zs'!$B$2,[1]ratio_ins!$B:$B,0))*$G5*INDEX([1]ratio_ins!$C:$C,MATCH('001_population_health_zone_zs'!$B5,[1]ratio_ins!$B:$B,0)) -> 22710.405 | Q5: =INDEX([1]ratio_ins!O:O,MATCH('001_population_health_zone_zs'!$B$2,[1]ratio_ins!$B:$B,0))*$G5*INDEX([1]ratio_ins!$C:$C,MATCH('001_population_health_zone_zs'!$B5,[1]ratio_ins!$B:$B,0)) -> 20264.669 | R5: =INDEX([1]ratio_ins!P:P,MATCH('001_population_health_zone_zs'!$B$2,[1]ratio_ins!$B:$B,0))*$G5*INDEX([1]ratio_ins!$C:$C,MATCH('001_population_health_zone_zs'!$B5,[1]ratio_ins!$B:$B,0)) -> 19915.278 | S5: =INDEX([1]ratio_ins!Q:Q,MATCH('001_population_health_zone_zs'!$B$2,[1]ratio_ins!$B:$B,0))*$G5*INDEX([1]ratio_ins!$C:$C,MATCH('001_population_health_zone_zs'!$B5,[1]ratio_ins!$B:$B,0)) -> 16770.76 | T5: =INDEX([1]ratio_ins!R:R,MATCH('001_population_health_zone_zs'!$B$2,[1]ratio_ins!$B:$B,0))*$G5*INDEX([1]ratio_ins!$C:$C,MATCH('001_population_health_zone_zs'!$B5,[1]ratio_ins!$B:$B,0)) -> 11879.289 | U5: =INDEX([1]ratio_ins!S:S,MATCH('001_population_health_zone_zs'!$B$2,[1]ratio_ins!$B:$B,0))*$G5*INDEX([1]ratio_ins!$C:$C,MATCH('001_population_health_zone_zs'!$B5,[1]ratio_ins!$B:$B,0)) -> 9433.5527 | V5: =INDEX([1]ratio_ins!T:T,MATCH('001_population_health_zone_zs'!$B$2,[1]ratio_ins!$B:$B,0))*$G5*INDEX([1]ratio_ins!$C:$C,MATCH('001_population_health_zone_zs'!$B5,[1]ratio_ins!$B:$B,0)) -> 5240.8626 | W5: =INDEX([1]ratio_ins!U:U,MATCH('001_population_health_zone_zs'!$B$2,[1]ratio_ins!$B:$B,0))*$G5*INDEX([1]ratio_ins!$C:$C,MATCH('001_population_health_zone_zs'!$B5,[1]ratio_ins!$B:$B,0)) -> 142970.73 | X5: =INDEX([1]ratio_ins!V:V,MATCH('001_population_health_zone_zs'!$B$2,[1]ratio_ins!$B:$B,0))*$G5*INDEX([1]ratio_ins!$C:$C,MATCH('001_population_health_zone_zs'!$B5,[1]ratio_ins!$B:$B,0)) -> 4192.6901 | Y5: =INDEX([1]ratio_ins!W:W,MATCH('001_population_health_zone_zs'!$B$2,[1]ratio_ins!$B:$B,0))*$G5*INDEX([1]ratio_ins!$C:$C,MATCH('001_population_health_zone_zs'!$B5,[1]ratio_ins!$B:$B,0)) -> 2795.1267 | Z5: =INDEX([1]ratio_ins!X:X,MATCH('001_population_health_zone_zs'!$B$2,[1]ratio_ins!$B:$B,0))*$G5*INDEX([1]ratio_ins!$C:$C,MATCH('001_population_health_zone_zs'!$B5,[1]ratio_ins!$B:$B,0)) -> 1397.5634 | AA5: =INDEX([1]ratio_ins!Y:Y,MATCH('001_population_health_zone_zs'!$B$2,[1]ratio_ins!$B:$B,0))*$G5*INDEX([1]ratio_ins!$C:$C,MATCH('001_population_health_zone_zs'!$B5,[1]ratio_ins!$B:$B,0)) -> 698.78168 | AB5: =INDEX([1]ratio_ins!Z:Z,MATCH('001_population_health_zone_zs'!$B$2,[1]ratio_ins!$B:$B,0))*$G5*INDEX([1]ratio_ins!$C:$C,MATCH('001_population_health_zone_zs'!$B5,[1]ratio_ins!$B:$B,0)) -> 9084.1619 | AC5: =M5+W5+AB5 -> 349390.84 | AD5: =INDEX([1]ratio_ins!AA:AA,MATCH('001_population_health_zone_zs'!$B$2,[1]ratio_ins!$B:$B,0))*$G5*INDEX([1]ratio_ins!$D:$D,MATCH('001_population_health_zone_zs'!$B5,[1]ratio_ins!$B:$B,0)) -> 72496.863 | AE5: =INDEX([1]ratio_ins!AB:AB,MATCH('001_population_health_zone_zs'!$B$2,[1]ratio_ins!$B:$B,0))*$G5*INDEX([1]ratio_ins!$D:$D,MATCH('001_population_health_zone_zs'!$B5,[1]ratio_ins!$B:$B,0)) -> 59723.606 | AF5: =INDEX([1]ratio_ins!AC:AC,MATCH('001_population_health_zone_zs'!$B$2,[1]ratio_ins!$B:$B,0))*$G5*INDEX([1]ratio_ins!$D:$D,MATCH('001_population_health_zone_zs'!$B5,[1]ratio_ins!$B:$B,0)) -> 47295.573 | AG5: =INDEX([1]ratio_ins!AD:AD,MATCH('001_population_health_zone_zs'!$B$2,[1]ratio_ins!$B:$B,0))*$G5*INDEX([1]ratio_ins!$D:$D,MATCH('001_population_health_zone_zs'!$B5,[1]ratio_ins!$B:$B,0)) -> 28653.522 | AH5: =INDEX([1]ratio_ins!AE:AE,MATCH('001_population_health_zone_zs'!$B$2,[1]ratio_ins!$B:$B,0))*$G5*INDEX([1]ratio_ins!$D:$D,MATCH('001_population_health_zone_zs'!$B5,[1]ratio_ins!$B:$B,0)) -> 17192.113 | AI5: =INDEX([1]ratio_ins!AF:AF,MATCH('001_population_health_zone_zs'!$B$2,[1]ratio_ins!$B:$B,0))*$G5*INDEX([1]ratio_ins!$D:$D,MATCH('001_population_health_zone_zs'!$B5,[1]ratio_ins!$B:$B,0)) -> 196708.16 | AJ5: =INDEX([1]ratio_ins!AG:AG,MATCH('001_population_health_zone_zs'!$B$2,[1]ratio_ins!$B:$B,0))*$G5*INDEX([1]ratio_ins!$D:$D,MATCH('001_population_health_zone_zs'!$B5,[1]ratio_ins!$B:$B,0)) -> 11461.409 | AK5: =INDEX([1]ratio_ins!AH:AH,MATCH('001_population_health_zone_zs'!$B$2,[1]ratio_ins!$B:$B,0))*$G5*INDEX([1]ratio_ins!$D:$D,MATCH('001_population_health_zone_zs'!$B5,[1]ratio_ins!$B:$B,0)) -> 25546.514 | AL5: =INDEX([1]ratio_ins!AI:AI,MATCH('001_population_health_zone_zs'!$B$2,[1]ratio_ins!$B:$B,0))*$G5*INDEX([1]ratio_ins!$D:$D,MATCH('001_population_health_zone_zs'!$B5,[1]ratio_ins!$B:$B,0)) -> 24165.621 | AM5: =INDEX([1]ratio_ins!AJ:AJ,MATCH('001_population_health_zone_zs'!$B$2,[1]ratio_ins!$B:$B,0))*$G5*INDEX([1]ratio_ins!$D:$D,MATCH('001_population_health_zone_zs'!$B5,[1]ratio_ins!$B:$B,0)) -> 22094.282 | AN5: =INDEX([1]ratio_ins!AK:AK,MATCH('001_population_health_zone_zs'!$B$2,[1]ratio_ins!$B:$B,0))*$G5*INDEX([1]ratio_ins!$D:$D,MATCH('001_population_health_zone_zs'!$B5,[1]ratio_ins!$B:$B,0)) -> 20713.389 | AO5: =INDEX([1]ratio_ins!AL:AL,MATCH('001_population_health_zone_zs'!$B$2,[1]ratio_ins!$B:$B,0))*$G5*INDEX([1]ratio_ins!$D:$D,MATCH('001_population_health_zone_zs'!$B5,[1]ratio_ins!$B:$B,0)) -> 15535.042 | AP5: =INDEX([1]ratio_ins!AM:AM,MATCH('001_population_health_zone_zs'!$B$2,[1]ratio_ins!$B:$B,0))*$G5*INDEX([1]ratio_ins!$D:$D,MATCH('001_population_health_zone_zs'!$B5,[1]ratio_ins!$B:$B,0)) -> 10011.472 | AQ5: =INDEX([1]ratio_ins!AN:AN,MATCH('001_population_health_zone_zs'!$B$2,[1]ratio_ins!$B:$B,0))*$G5*INDEX([1]ratio_ins!$D:$D,MATCH('001_population_health_zone_zs'!$B5,[1]ratio_ins!$B:$B,0)) -> 7940.1326 | AR5: =INDEX([1]ratio_ins!AO:AO,MATCH('001_population_health_zone_zs'!$B$2,[1]ratio_ins!$B:$B,0))*$G5*INDEX([1]ratio_ins!$D:$D,MATCH('001_population_health_zone_zs'!$B5,[1]ratio_ins!$B:$B,0)) -> 3797.4547 | AS5: =INDEX([1]ratio_ins!AP:AP,MATCH('001_population_health_zone_zs'!$B$2,[1]ratio_ins!$B:$B,0))*$G5*INDEX([1]ratio_ins!$D:$D,MATCH('001_population_health_zone_zs'!$B5,[1]ratio_ins!$B:$B,0)) -> 141265.32 | AT5: =INDEX([1]ratio_ins!AQ:AQ,MATCH('001_population_health_zone_zs'!$B$2,[1]ratio_ins!$B:$B,0))*$G5*INDEX([1]ratio_ins!$D:$D,MATCH('001_population_health_zone_zs'!$B5,[1]ratio_ins!$B:$B,0)) -> 3452.2316 | AU5: =INDEX([1]ratio_ins!AR:AR,MATCH('001_population_health_zone_zs'!$B$2,[1]ratio_ins!$B:$B,0))*$G5*INDEX([1]ratio_ins!$D:$D,MATCH('001_population_health_zone_zs'!$B5,[1]ratio_ins!$B:$B,0)) -> 2071.3389 | AV5: =INDEX([1]ratio_ins!AS:AS,MATCH('001_population_health_zone_zs'!$B$2,[1]ratio_ins!$B:$B,0))*$G5*INDEX([1]ratio_ins!$D:$D,MATCH('001_population_health_zone_zs'!$B5,[1]ratio_ins!$B:$B,0)) -> 1035.6695 | AW5: =INDEX([1]ratio_ins!AT:AT,MATCH('001_population_health_zone_zs'!$B$2,[1]ratio_ins!$B:$B,0))*$G5*INDEX([1]ratio_ins!$D:$D,MATCH('001_population_health_zone_zs'!$B5,[1]ratio_ins!$B:$B,0)) -> 690.44632 | AX5: =INDEX([1]ratio_ins!AU:AU,MATCH('001_population_health_zone_zs'!$B$2,[1]ratio_ins!$B:$B,0))*$G5*INDEX([1]ratio_ins!$D:$D,MATCH('001_population_health_zone_zs'!$B5,[1]ratio_ins!$B:$B,0)) -> 7249.6863 | AY5: =AI5+AS5+AX5 -> 345223.16 | AZ5: =AC5+AY5 -> 694614 | BA5: 686577.66 | BB5: =SUM(AH5,AJ5,AK5:AP5) -> 146719.84 | BC5: =BB5/G5 -> 0.211225 | BD5: =SUM(L5,N5:T5) -> 145695.98
A6: Kinshasa | B6: CD10 | C6: Kinshasa | D6: CD1000 | E6: Biyela | F6: CD1000ZS05 | G6: 417747 | H6: =INDEX([1]ratio_ins!F:F,MATCH('001_population_health_zone_zs'!$B$2,[1]ratio_ins!$B:$B,0))*$G6*INDEX([1]ratio_ins!$C:$C,MATCH('001_population_health_zone_zs'!$B6,[1]ratio_ins!$B:$B,0)) -> 43916.489 | I6: =INDEX([1]ratio_ins!G:G,MATCH('001_population_health_zone_zs'!$B$2,[1]ratio_ins!$B:$B,0))*$G6*INDEX([1]ratio_ins!$C:$C,MATCH('001_population_health_zone_zs'!$B6,[1]ratio_ins!$B:$B,0)) -> 35931.673 | J6: =INDEX([1]ratio_ins!H:H,MATCH('001_population_health_zone_zs'!$B$2,[1]ratio_ins!$B:$B,0))*$G6*INDEX([1]ratio_ins!$C:$C,MATCH('001_population_health_zone_zs'!$B6,[1]ratio_ins!$B:$B,0)) -> 28367.11 | K6: =INDEX([1]ratio_ins!I:I,MATCH('001_population_health_zone_zs'!$B$2,[1]ratio_ins!$B:$B,0))*$G6*INDEX([1]ratio_ins!$C:$C,MATCH('001_population_health_zone_zs'!$B6,[1]ratio_ins!$B:$B,0)) -> 17440.52 | L6: =INDEX([1]ratio_ins!J:J,MATCH('001_population_health_zone_zs'!$B$2,[1]ratio_ins!$B:$B,0))*$G6*INDEX([1]ratio_ins!$C:$C,MATCH('001_population_health_zone_zs'!$B6,[1]ratio_ins!$B:$B,0)) -> 10464.312 | M6: =INDEX([1]ratio_ins!K:K,MATCH('001_population_health_zone_zs'!$B$2,[1]ratio_ins!$B:$B,0))*$G6*INDEX([1]ratio_ins!$C:$C,MATCH('001_population_health_zone_zs'!$B6,[1]ratio_ins!$B:$B,0)) -> 118679.58 | N6: =INDEX([1]ratio_ins!L:L,MATCH('001_population_health_zone_zs'!$B$2,[1]ratio_ins!$B:$B,0))*$G6*INDEX([1]ratio_ins!$C:$C,MATCH('001_population_health_zone_zs'!$B6,[1]ratio_ins!$B:$B,0)) -> 6976.2078 | O6: =INDEX([1]ratio_ins!M:M,MATCH('001_population_health_zone_zs'!$B$2,[1]ratio_ins!$B:$B,0))*$G6*INDEX([1]ratio_ins!$C:$C,MATCH('001_population_health_zone_zs'!$B6,[1]ratio_ins!$B:$B,0)) -> 15129.125 | P6: =INDEX([1]ratio_ins!N:N,MATCH('001_population_health_zone_zs'!$B$2,[1]ratio_ins!$B:$B,0))*$G6*INDEX([1]ratio_ins!$C:$C,MATCH('001_population_health_zone_zs'!$B6,[1]ratio_ins!$B:$B,0)) -> 13658.238 | Q6: =INDEX([1]ratio_ins!O:O,MATCH('001_population_health_zone_zs'!$B$2,[1]ratio_ins!$B:$B,0))*$G6*INDEX([1]ratio_ins!$C:$C,MATCH('001_population_health_zone_zs'!$B6,[1]ratio_ins!$B:$B,0)) -> 12187.351 | R6: =INDEX([1]ratio_ins!P:P,MATCH('001_population_health_zone_zs'!$B$2,[1]ratio_ins!$B:$B,0))*$G6*INDEX([1]ratio_ins!$C:$C,MATCH('001_population_health_zone_zs'!$B6,[1]ratio_ins!$B:$B,0)) -> 11977.224 | S6: =INDEX([1]ratio_ins!Q:Q,MATCH('001_population_health_zone_zs'!$B$2,[1]ratio_ins!$B:$B,0))*$G6*INDEX([1]ratio_ins!$C:$C,MATCH('001_population_health_zone_zs'!$B6,[1]ratio_ins!$B:$B,0)) -> 10086.084 | T6: =INDEX([1]ratio_ins!R:R,MATCH('001_population_health_zone_zs'!$B$2,[1]ratio_ins!$B:$B,0))*$G6*INDEX([1]ratio_ins!$C:$C,MATCH('001_population_health_zone_zs'!$B6,[1]ratio_ins!$B:$B,0)) -> 7144.3092 | U6: =INDEX([1]ratio_ins!S:S,MATCH('001_population_health_zone_zs'!$B$2,[1]ratio_ins!$B:$B,0))*$G6*INDEX([1]ratio_ins!$C:$C,MATCH('001_population_health_zone_zs'!$B6,[1]ratio_ins!$B:$B,0)) -> 5673.422 | V6: =INDEX([1]ratio_ins!T:T,MATCH('001_population_health_zone_zs'!$B$2,[1]ratio_ins!$B:$B,0))*$G6*INDEX([1]ratio_ins!$C:$C,MATCH('001_population_health_zone_zs'!$B6,[1]ratio_ins!$B:$B,0)) -> 3151.9011 | W6: =INDEX([1]ratio_ins!U:U,MATCH('001_population_health_zone_zs'!$B$2,[1]ratio_ins!$B:$B,0))*$G6*INDEX([1]ratio_ins!$C:$C,MATCH('001_population_health_zone_zs'!$B6,[1]ratio_ins!$B:$B,0)) -> 85983.862 | X6: =INDEX([1]ratio_ins!V:V,MATCH('001_population_health_zone_zs'!$B$2,[1]ratio_ins!$B:$B,0))*$G6*INDEX([1]ratio_ins!$C:$C,MATCH('001_population_health_zone_zs'!$B6,[1]ratio_ins!$B:$B,0)) -> 2521.5209 | Y6: =INDEX([1]ratio_ins!W:W,MATCH('001_population_health_zone_zs'!$B$2,[1]ratio_ins!$B:$B,0))*$G6*INDEX([1]ratio_ins!$C:$C,MATCH('001_population_health_zone_zs'!$B6,[1]ratio_ins!$B:$B,0)) -> 1681.0139 | Z6: =INDEX([1]ratio_ins!X:X,MATCH('001_population_health_zone_zs'!$B$2,[1]ratio_ins!$B:$B,0))*$G6*INDEX([1]ratio_ins!$C:$C,MATCH('001_population_health_zone_zs'!$B6,[1]ratio_ins!$B:$B,0)) -> 840.50696 | AA6: =INDEX([1]ratio_ins!Y:Y,MATCH('001_population_health_zone_zs'!$B$2,[1]ratio_ins!$B:$B,0))*$G6*INDEX([1]ratio_ins!$C:$C,MATCH('001_population_health_zone_zs'!$B6,[1]ratio_ins!$B:$B,0)) -> 420.25348 | AB6: =INDEX([1]ratio_ins!Z:Z,MATCH('001_population_health_zone_zs'!$B$2,[1]ratio_ins!$B:$B,0))*$G6*INDEX([1]ratio_ins!$C:$C,MATCH('001_population_health_zone_zs'!$B6,[1]ratio_ins!$B:$B,0)) -> 5463.2953 | AC6: =M6+W6+AB6 -> 210126.74 | AD6: =INDEX([1]ratio_ins!AA:AA,MATCH('001_population_health_zone_zs'!$B$2,[1]ratio_ins!$B:$B,0))*$G6*INDEX([1]ratio_ins!$D:$D,MATCH('001_population_health_zone_zs'!$B6,[1]ratio_ins!$B:$B,0)) -> 43600.254 | AE6: =INDEX([1]ratio_ins!AB:AB,MATCH('001_population_health_zone_zs'!$B$2,[1]ratio_ins!$B:$B,0))*$G6*INDEX([1]ratio_ins!$D:$D,MATCH('001_population_health_zone_zs'!$B6,[1]ratio_ins!$B:$B,0)) -> 35918.305 | AF6: =INDEX([1]ratio_ins!AC:AC,MATCH('001_population_health_zone_zs'!$B$2,[1]ratio_ins!$B:$B,0))*$G6*INDEX([1]ratio_ins!$D:$D,MATCH('001_population_health_zone_zs'!$B6,[1]ratio_ins!$B:$B,0)) -> 28443.975 | AG6: =INDEX([1]ratio_ins!AD:AD,MATCH('001_population_health_zone_zs'!$B$2,[1]ratio_ins!$B:$B,0))*$G6*INDEX([1]ratio_ins!$D:$D,MATCH('001_population_health_zone_zs'!$B6,[1]ratio_ins!$B:$B,0)) -> 17232.481 | AH6: =INDEX([1]ratio_ins!AE:AE,MATCH('001_population_health_zone_zs'!$B$2,[1]ratio_ins!$B:$B,0))*$G6*INDEX([1]ratio_ins!$D:$D,MATCH('001_population_health_zone_zs'!$B6,[1]ratio_ins!$B:$B,0)) -> 10339.489 | AI6: =INDEX([1]ratio_ins!AF:AF,MATCH('001_population_health_zone_zs'!$B$2,[1]ratio_ins!$B:$B,0))*$G6*INDEX([1]ratio_ins!$D:$D,MATCH('001_population_health_zone_zs'!$B6,[1]ratio_ins!$B:$B,0)) -> 118302.02 | AJ6: =INDEX([1]ratio_ins!AG:AG,MATCH('001_population_health_zone_zs'!$B$2,[1]ratio_ins!$B:$B,0))*$G6*INDEX([1]ratio_ins!$D:$D,MATCH('001_population_health_zone_zs'!$B6,[1]ratio_ins!$B:$B,0)) -> 6892.9926 | AK6: =INDEX([1]ratio_ins!AH:AH,MATCH('001_population_health_zone_zs'!$B$2,[1]ratio_ins!$B:$B,0))*$G6*INDEX([1]ratio_ins!$D:$D,MATCH('001_population_health_zone_zs'!$B6,[1]ratio_ins!$B:$B,0)) -> 15363.899 | AL6: =INDEX([1]ratio_ins!AI:AI,MATCH('001_population_health_zone_zs'!$B$2,[1]ratio_ins!$B:$B,0))*$G6*INDEX([1]ratio_ins!$D:$D,MATCH('001_population_health_zone_zs'!$B6,[1]ratio_ins!$B:$B,0)) -> 14533.418 | AM6: =INDEX([1]ratio_ins!AJ:AJ,MATCH('001_population_health_zone_zs'!$B$2,[1]ratio_ins!$B:$B,0))*$G6*INDEX([1]ratio_ins!$D:$D,MATCH('001_population_health_zone_zs'!$B6,[1]ratio_ins!$B:$B,0)) -> 13287.697 | AN6: =INDEX([1]ratio_ins!AK:AK,MATCH('001_population_health_zone_zs'!$B$2,[1]ratio_ins!$B:$B,0))*$G6*INDEX([1]ratio_ins!$D:$D,MATCH('001_population_health_zone_zs'!$B6,[1]ratio_ins!$B:$B,0)) -> 12457.216 | AO6: =INDEX([1]ratio_ins!AL:AL,MATCH('001_population_health_zone_zs'!$B$2,[1]ratio_ins!$B:$B,0))*$G6*INDEX([1]ratio_ins!$D:$D,MATCH('001_population_health_zone_zs'!$B6,[1]ratio_ins!$B:$B,0)) -> 9342.9117 | AP6: =INDEX([1]ratio_ins!AM:AM,MATCH('001_population_health_zone_zs'!$B$2,[1]ratio_ins!$B:$B,0))*$G6*INDEX([1]ratio_ins!$D:$D,MATCH('001_population_health_zone_zs'!$B6,[1]ratio_ins!$B:$B,0)) -> 6020.9875 | AQ6: =INDEX([1]ratio_ins!AN:AN,MATCH('001_population_health_zone_zs'!$B$2,[1]ratio_ins!$B:$B,0))*$G6*INDEX([1]ratio_ins!$D:$D,MATCH('001_population_health_zone_zs'!$B6,[1]ratio_ins!$B:$B,0)) -> 4775.266 | AR6: =INDEX([1]ratio_ins!AO:AO,MATCH('001_population_health_zone_zs'!$B$2,[1]ratio_ins!$B:$B,0))*$G6*INDEX([1]ratio_ins!$D:$D,MATCH('001_population_health_zone_zs'!$B6,[1]ratio_ins!$B:$B,0)) -> 2283.8228 | AS6: =INDEX([1]ratio_ins!AP:AP,MATCH('001_population_health_zone_zs'!$B$2,[1]ratio_ins!$B:$B,0))*$G6*INDEX([1]ratio_ins!$D:$D,MATCH('001_population_health_zone_zs'!$B6,[1]ratio_ins!$B:$B,0)) -> 84958.21 | AT6: =INDEX([1]ratio_ins!AQ:AQ,MATCH('001_population_health_zone_zs'!$B$2,[1]ratio_ins!$B:$B,0))*$G6*INDEX([1]ratio_ins!$D:$D,MATCH('001_population_health_zone_zs'!$B6,[1]ratio_ins!$B:$B,0)) -> 2076.2026 | AU6: =INDEX([1]ratio_ins!AR:AR,MATCH('001_population_health_zone_zs'!$B$2,[1]ratio_ins!$B:$B,0))*$G6*INDEX([1]ratio_ins!$D:$D,MATCH('001_population_health_zone_zs'!$B6,[1]ratio_ins!$B:$B,0)) -> 1245.7216 | AV6: =INDEX([1]ratio_ins!AS:AS,MATCH('001_population_health_zone_zs'!$B$2,[1]ratio_ins!$B:$B,0))*$G6*INDEX([1]ratio_ins!$D:$D,MATCH('001_population_health_zone_zs'!$B6,[1]ratio_ins!$B:$B,0)) -> 622.86078 | AW6: =INDEX([1]ratio_ins!AT:AT,MATCH('001_population_health_zone_zs'!$B$2,[1]ratio_ins!$B:$B,0))*$G6*INDEX([1]ratio_ins!$D:$D,MATCH('001_population_health_zone_zs'!$B6,[1]ratio_ins!$B:$B,0)) -> 415.24052 | AX6: =INDEX([1]ratio_ins!AU:AU,MATCH('001_population_health_zone_zs'!$B$2,[1]ratio_ins!$B:$B,0))*$G6*INDEX([1]ratio_ins!$D:$D,MATCH('001_population_health_zone_zs'!$B6,[1]ratio_ins!$B:$B,0)) -> 4360.0254 | AY6: =AI6+AS6+AX6 -> 207620.26 | AZ6: =AC6+AY6 -> 417747 | BA6: 412913.56 | BB6: =SUM(AH6,AJ6,AK6:AP6) -> 88238.61 | BC6: =BB6/G6 -> 0.211225 | BD6: =SUM(L6,N6:T6) -> 87622.851
A7: Kinshasa | B7: CD10 | C7: Kinshasa | D7: CD1000 | E7: Bumbu | F7: CD1000ZS06 | G7: 769113 | H7: =INDEX([1]ratio_ins!F:F,MATCH('001_population_health_zone_zs'!$B$2,[1]ratio_ins!$B:$B,0))*$G7*INDEX([1]ratio_ins!$C:$C,MATCH('001_population_health_zone_zs'!$B7,[1]ratio_ins!$B:$B,0)) -> 80854.542 | I7: =INDEX([1]ratio_ins!G:G,MATCH('001_population_health_zone_zs'!$B$2,[1]ratio_ins!$B:$B,0))*$G7*INDEX([1]ratio_ins!$C:$C,MATCH('001_population_health_zone_zs'!$B7,[1]ratio_ins!$B:$B,0)) -> 66153.716 | J7: =INDEX([1]ratio_ins!H:H,MATCH('001_population_health_zone_zs'!$B$2,[1]ratio_ins!$B:$B,0))*$G7*INDEX([1]ratio_ins!$C:$C,MATCH('001_population_health_zone_zs'!$B7,[1]ratio_ins!$B:$B,0)) -> 52226.618 | K7: =INDEX([1]ratio_ins!I:I,MATCH('001_population_health_zone_zs'!$B$2,[1]ratio_ins!$B:$B,0))*$G7*INDEX([1]ratio_ins!$C:$C,MATCH('001_population_health_zone_zs'!$B7,[1]ratio_ins!$B:$B,0)) -> 32109.699 | L7: =INDEX([1]ratio_ins!J:J,MATCH('001_population_health_zone_zs'!$B$2,[1]ratio_ins!$B:$B,0))*$G7*INDEX([1]ratio_ins!$C:$C,MATCH('001_population_health_zone_zs'!$B7,[1]ratio_ins!$B:$B,0)) -> 19265.819 | M7: =INDEX([1]ratio_ins!K:K,MATCH('001_population_health_zone_zs'!$B$2,[1]ratio_ins!$B:$B,0))*$G7*INDEX([1]ratio_ins!$C:$C,MATCH('001_population_health_zone_zs'!$B7,[1]ratio_ins!$B:$B,0)) -> 218500.7 | N7: =INDEX([1]ratio_ins!L:L,MATCH('001_population_health_zone_zs'!$B$2,[1]ratio_ins!$B:$B,0))*$G7*INDEX([1]ratio_ins!$C:$C,MATCH('001_population_health_zone_zs'!$B7,[1]ratio_ins!$B:$B,0)) -> 12843.879 | O7: =INDEX([1]ratio_ins!M:M,MATCH('001_population_health_zone_zs'!$B$2,[1]ratio_ins!$B:$B,0))*$G7*INDEX([1]ratio_ins!$C:$C,MATCH('001_population_health_zone_zs'!$B7,[1]ratio_ins!$B:$B,0)) -> 27854.196 | P7: =INDEX([1]ratio_ins!N:N,MATCH('001_population_health_zone_zs'!$B$2,[1]ratio_ins!$B:$B,0))*$G7*INDEX([1]ratio_ins!$C:$C,MATCH('001_population_health_zone_zs'!$B7,[1]ratio_ins!$B:$B,0)) -> 25146.15 | Q7: =INDEX([1]ratio_ins!O:O,MATCH('001_population_health_zone_zs'!$B$2,[1]ratio_ins!$B:$B,0))*$G7*INDEX([1]ratio_ins!$C:$C,MATCH('001_population_health_zone_zs'!$B7,[1]ratio_ins!$B:$B,0)) -> 22438.103 | R7: =INDEX([1]ratio_ins!P:P,MATCH('001_population_health_zone_zs'!$B$2,[1]ratio_ins!$B:$B,0))*$G7*INDEX([1]ratio_ins!$C:$C,MATCH('001_population_health_zone_zs'!$B7,[1]ratio_ins!$B:$B,0)) -> 22051.239 | S7: =INDEX([1]ratio_ins!Q:Q,MATCH('001_population_health_zone_zs'!$B$2,[1]ratio_ins!$B:$B,0))*$G7*INDEX([1]ratio_ins!$C:$C,MATCH('001_population_health_zone_zs'!$B7,[1]ratio_ins!$B:$B,0)) -> 18569.464 | T7: =INDEX([1]ratio_ins!R:R,MATCH('001_population_health_zone_zs'!$B$2,[1]ratio_ins!$B:$B,0))*$G7*INDEX([1]ratio_ins!$C:$C,MATCH('001_population_health_zone_zs'!$B7,[1]ratio_ins!$B:$B,0)) -> 13153.371 | U7: =INDEX([1]ratio_ins!S:S,MATCH('001_population_health_zone_zs'!$B$2,[1]ratio_ins!$B:$B,0))*$G7*INDEX([1]ratio_ins!$C:$C,MATCH('001_population_health_zone_zs'!$B7,[1]ratio_ins!$B:$B,0)) -> 10445.324 | V7: =INDEX([1]ratio_ins!T:T,MATCH('001_population_health_zone_zs'!$B$2,[1]ratio_ins!$B:$B,0))*$G7*INDEX([1]ratio_ins!$C:$C,MATCH('001_population_health_zone_zs'!$B7,[1]ratio_ins!$B:$B,0)) -> 5802.9576 | W7: =INDEX([1]ratio_ins!U:U,MATCH('001_population_health_zone_zs'!$B$2,[1]ratio_ins!$B:$B,0))*$G7*INDEX([1]ratio_ins!$C:$C,MATCH('001_population_health_zone_zs'!$B7,[1]ratio_ins!$B:$B,0)) -> 158304.68 | X7: =INDEX([1]ratio_ins!V:V,MATCH('001_population_health_zone_zs'!$B$2,[1]ratio_ins!$B:$B,0))*$G7*INDEX([1]ratio_ins!$C:$C,MATCH('001_population_health_zone_zs'!$B7,[1]ratio_ins!$B:$B,0)) -> 4642.3661 | Y7: =INDEX([1]ratio_ins!W:W,MATCH('001_population_health_zone_zs'!$B$2,[1]ratio_ins!$B:$B,0))*$G7*INDEX([1]ratio_ins!$C:$C,MATCH('001_population_health_zone_zs'!$B7,[1]ratio_ins!$B:$B,0)) -> 3094.9107 | Z7: =INDEX([1]ratio_ins!X:X,MATCH('001_population_health_zone_zs'!$B$2,[1]ratio_ins!$B:$B,0))*$G7*INDEX([1]ratio_ins!$C:$C,MATCH('001_population_health_zone_zs'!$B7,[1]ratio_ins!$B:$B,0)) -> 1547.4554 | AA7: =INDEX([1]ratio_ins!Y:Y,MATCH('001_population_health_zone_zs'!$B$2,[1]ratio_ins!$B:$B,0))*$G7*INDEX([1]ratio_ins!$C:$C,MATCH('001_population_health_zone_zs'!$B7,[1]ratio_ins!$B:$B,0)) -> 773.72768 | AB7: =INDEX([1]ratio_ins!Z:Z,MATCH('001_population_health_zone_zs'!$B$2,[1]ratio_ins!$B:$B,0))*$G7*INDEX([1]ratio_ins!$C:$C,MATCH('001_population_health_zone_zs'!$B7,[1]ratio_ins!$B:$B,0)) -> 10058.46 | AC7: =M7+W7+AB7 -> 386863.84 | AD7: =INDEX([1]ratio_ins!AA:AA,MATCH('001_population_health_zone_zs'!$B$2,[1]ratio_ins!$B:$B,0))*$G7*INDEX([1]ratio_ins!$D:$D,MATCH('001_population_health_zone_zs'!$B7,[1]ratio_ins!$B:$B,0)) -> 80272.324 | AE7: =INDEX([1]ratio_ins!AB:AB,MATCH('001_population_health_zone_zs'!$B$2,[1]ratio_ins!$B:$B,0))*$G7*INDEX([1]ratio_ins!$D:$D,MATCH('001_population_health_zone_zs'!$B7,[1]ratio_ins!$B:$B,0)) -> 66129.105 | AF7: =INDEX([1]ratio_ins!AC:AC,MATCH('001_population_health_zone_zs'!$B$2,[1]ratio_ins!$B:$B,0))*$G7*INDEX([1]ratio_ins!$D:$D,MATCH('001_population_health_zone_zs'!$B7,[1]ratio_ins!$B:$B,0)) -> 52368.135 | AG7: =INDEX([1]ratio_ins!AD:AD,MATCH('001_population_health_zone_zs'!$B$2,[1]ratio_ins!$B:$B,0))*$G7*INDEX([1]ratio_ins!$D:$D,MATCH('001_population_health_zone_zs'!$B7,[1]ratio_ins!$B:$B,0)) -> 31726.68 | AH7: =INDEX([1]ratio_ins!AE:AE,MATCH('001_population_health_zone_zs'!$B$2,[1]ratio_ins!$B:$B,0))*$G7*INDEX([1]ratio_ins!$D:$D,MATCH('001_population_health_zone_zs'!$B7,[1]ratio_ins!$B:$B,0)) -> 19036.008 | AI7: =INDEX([1]ratio_ins!AF:AF,MATCH('001_population_health_zone_zs'!$B$2,[1]ratio_ins!$B:$B,0))*$G7*INDEX([1]ratio_ins!$D:$D,MATCH('001_population_health_zone_zs'!$B7,[1]ratio_ins!$B:$B,0)) -> 217805.57 | AJ7: =INDEX([1]ratio_ins!AG:AG,MATCH('001_population_health_zone_zs'!$B$2,[1]ratio_ins!$B:$B,0))*$G7*INDEX([1]ratio_ins!$D:$D,MATCH('001_population_health_zone_zs'!$B7,[1]ratio_ins!$B:$B,0)) -> 12690.672 | AK7: =INDEX([1]ratio_ins!AH:AH,MATCH('001_population_health_zone_zs'!$B$2,[1]ratio_ins!$B:$B,0))*$G7*INDEX([1]ratio_ins!$D:$D,MATCH('001_population_health_zone_zs'!$B7,[1]ratio_ins!$B:$B,0)) -> 28286.438 | AL7: =INDEX([1]ratio_ins!AI:AI,MATCH('001_population_health_zone_zs'!$B$2,[1]ratio_ins!$B:$B,0))*$G7*INDEX([1]ratio_ins!$D:$D,MATCH('001_population_health_zone_zs'!$B7,[1]ratio_ins!$B:$B,0)) -> 26757.441 | AM7: =INDEX([1]ratio_ins!AJ:AJ,MATCH('001_population_health_zone_zs'!$B$2,[1]ratio_ins!$B:$B,0))*$G7*INDEX([1]ratio_ins!$D:$D,MATCH('001_population_health_zone_zs'!$B7,[1]ratio_ins!$B:$B,0)) -> 24463.946 | AN7: =INDEX([1]ratio_ins!AK:AK,MATCH('001_population_health_zone_zs'!$B$2,[1]ratio_ins!$B:$B,0))*$G7*INDEX([1]ratio_ins!$D:$D,MATCH('001_population_health_zone_zs'!$B7,[1]ratio_ins!$B:$B,0)) -> 22934.95 | AO7: =INDEX([1]ratio_ins!AL:AL,MATCH('001_population_health_zone_zs'!$B$2,[1]ratio_ins!$B:$B,0))*$G7*INDEX([1]ratio_ins!$D:$D,MATCH('001_population_health_zone_zs'!$B7,[1]ratio_ins!$B:$B,0)) -> 17201.212 | AP7: =INDEX([1]ratio_ins!AM:AM,MATCH('001_population_health_zone_zs'!$B$2,[1]ratio_ins!$B:$B,0))*$G7*INDEX([1]ratio_ins!$D:$D,MATCH('001_population_health_zone_zs'!$B7,[1]ratio_ins!$B:$B,0)) -> 11085.226 | AQ7: =INDEX([1]ratio_ins!AN:AN,MATCH('001_population_health_zone_zs'!$B$2,[1]ratio_ins!$B:$B,0))*$G7*INDEX([1]ratio_ins!$D:$D,MATCH('001_population_health_zone_zs'!$B7,[1]ratio_ins!$B:$B,0)) -> 8791.7307 | AR7: =INDEX([1]ratio_ins!AO:AO,MATCH('001_population_health_zone_zs'!$B$2,[1]ratio_ins!$B:$B,0))*$G7*INDEX([1]ratio_ins!$D:$D,MATCH('001_population_health_zone_zs'!$B7,[1]ratio_ins!$B:$B,0)) -> 4204.7408 | AS7: =INDEX([1]ratio_ins!AP:AP,MATCH('001_population_health_zone_zs'!$B$2,[1]ratio_ins!$B:$B,0))*$G7*INDEX([1]ratio_ins!$D:$D,MATCH('001_population_health_zone_zs'!$B7,[1]ratio_ins!$B:$B,0)) -> 156416.36 | AT7: =INDEX([1]ratio_ins!AQ:AQ,MATCH('001_population_health_zone_zs'!$B$2,[1]ratio_ins!$B:$B,0))*$G7*INDEX([1]ratio_ins!$D:$D,MATCH('001_population_health_zone_zs'!$B7,[1]ratio_ins!$B:$B,0)) -> 3822.4916 | AU7: =INDEX([1]ratio_ins!AR:AR,MATCH('001_population_health_zone_zs'!$B$2,[1]ratio_ins!$B:$B,0))*$G7*INDEX([1]ratio_ins!$D:$D,MATCH('001_population_health_zone_zs'!$B7,[1]ratio_ins!$B:$B,0)) -> 2293.495 | AV7: =INDEX([1]ratio_ins!AS:AS,MATCH('001_population_health_zone_zs'!$B$2,[1]ratio_ins!$B:$B,0))*$G7*INDEX([1]ratio_ins!$D:$D,MATCH('001_population_health_zone_zs'!$B7,[1]ratio_ins!$B:$B,0)) -> 1146.7475 | AW7: =INDEX([1]ratio_ins!AT:AT,MATCH('001_population_health_zone_zs'!$B$2,[1]ratio_ins!$B:$B,0))*$G7*INDEX([1]ratio_ins!$D:$D,MATCH('001_population_health_zone_zs'!$B7,[1]ratio_ins!$B:$B,0)) -> 764.49832 | AX7: =INDEX([1]ratio_ins!AU:AU,MATCH('001_population_health_zone_zs'!$B$2,[1]ratio_ins!$B:$B,0))*$G7*INDEX([1]ratio_ins!$D:$D,MATCH('001_population_health_zone_zs'!$B7,[1]ratio_ins!$B:$B,0)) -> 8027.2324 | AY7: =AI7+AS7+AX7 -> 382249.16 | AZ7: =AC7+AY7 -> 769113 | BA7: 760215.12 | BB7: =SUM(AH7,AJ7,AK7:AP7) -> 162455.89 | BC7: =BB7/G7 -> 0.211225 | BD7: =SUM(L7,N7:T7) -> 161322.22
